<?xml version="1.0" encoding="UTF-8"?>
<testng-results ignored="0" total="2" passed="0" failed="2" skipped="0">
  <reporter-output>
  </reporter-output>
  <suite started-at="2020-02-01T10:08:46Z" name="Failed suite [Default suite]" finished-at="2020-02-01T10:09:16Z" duration-ms="30542">
    <groups>
    </groups>
    <test started-at="2020-02-01T10:08:46Z" name="Default test(failed)" finished-at="2020-02-01T10:09:16Z" duration-ms="30542">
      <class name="com.netbanking.testcases.TC_LoginDDT_002">
        <test-method is-config="true" signature="setUp()[pri:0, instance:com.netbanking.testcases.TC_LoginDDT_002@186f8716]" started-at="2020-02-01T10:08:46Z" name="setUp" finished-at="2020-02-01T10:08:57Z" duration-ms="11739" status="PASS">
          <reporter-output>
          </reporter-output>
        </test-method> <!-- setUp -->
        <test-method signature="loginDDT(java.lang.String, java.lang.String)[pri:0, instance:com.netbanking.testcases.TC_LoginDDT_002@186f8716]" started-at="2020-02-01T10:08:59Z" name="loginDDT" data-provider="LoginData" finished-at="2020-02-01T10:09:06Z" duration-ms="7103" status="FAIL">
          <params>
            <param index="0">
              <value>
                <![CDATA[mngr4561234]]>
              </value>
            </param>
            <param index="1">
              <value>
                <![CDATA[Jaisri#2018]]>
              </value>
            </param>
          </params>
          <exception class="junit.framework.AssertionFailedError">
            <full-stacktrace>
              <![CDATA[junit.framework.AssertionFailedError
at junit.framework.Assert.fail(Assert.java:47)
at junit.framework.Assert.assertTrue(Assert.java:20)
at junit.framework.Assert.assertTrue(Assert.java:27)
at com.netbanking.testcases.TC_LoginDDT_002.loginDDT(TC_LoginDDT_002.java:37)
at java.base/jdk.internal.reflect.NativeMethodAccessorImpl.invoke0(Native Method)
at java.base/jdk.internal.reflect.NativeMethodAccessorImpl.invoke(Unknown Source)
at java.base/jdk.internal.reflect.DelegatingMethodAccessorImpl.invoke(Unknown Source)
at java.base/java.lang.reflect.Method.invoke(Unknown Source)
at org.testng.internal.MethodInvocationHelper.invokeMethod(MethodInvocationHelper.java:124)
at org.testng.internal.Invoker.invokeMethod(Invoker.java:583)
at org.testng.internal.Invoker.invokeTestMethod(Invoker.java:719)
at org.testng.internal.Invoker.invokeTestMethods(Invoker.java:989)
at org.testng.internal.TestMethodWorker.invokeTestMethods(TestMethodWorker.java:125)
at org.testng.internal.TestMethodWorker.run(TestMethodWorker.java:109)
at org.testng.TestRunner.privateRun(TestRunner.java:648)
at org.testng.TestRunner.run(TestRunner.java:505)
at org.testng.SuiteRunner.runTest(SuiteRunner.java:455)
at org.testng.SuiteRunner.runSequentially(SuiteRunner.java:450)
at org.testng.SuiteRunner.privateRun(SuiteRunner.java:415)
at org.testng.SuiteRunner.run(SuiteRunner.java:364)
at org.testng.SuiteRunnerWorker.runSuite(SuiteRunnerWorker.java:52)
at org.testng.SuiteRunnerWorker.run(SuiteRunnerWorker.java:84)
at org.testng.TestNG.runSuitesSequentially(TestNG.java:1208)
at org.testng.TestNG.runSuitesLocally(TestNG.java:1137)
at org.testng.TestNG.runSuites(TestNG.java:1049)
at org.testng.TestNG.run(TestNG.java:1017)
at org.testng.remote.AbstractRemoteTestNG.run(AbstractRemoteTestNG.java:114)
at org.testng.remote.RemoteTestNG.initAndRun(RemoteTestNG.java:251)
at org.testng.remote.RemoteTestNG.main(RemoteTestNG.java:77)
]]>
            </full-stacktrace>
          </exception> <!-- junit.framework.AssertionFailedError -->
          <reporter-output>
          </reporter-output>
        </test-method> <!-- loginDDT -->
        <test-method signature="loginDDT(java.lang.String, java.lang.String)[pri:0, instance:com.netbanking.testcases.TC_LoginDDT_002@186f8716]" started-at="2020-02-01T10:09:06Z" name="loginDDT" data-provider="LoginData" finished-at="2020-02-01T10:09:15Z" duration-ms="9068" status="FAIL">
          <params>
            <param index="0">
              <value>
                <![CDATA[mngr56hyt12]]>
              </value>
            </param>
            <param index="1">
              <value>
                <![CDATA[iuytrw]]>
              </value>
            </param>
          </params>
          <exception class="junit.framework.AssertionFailedError">
            <full-stacktrace>
              <![CDATA[junit.framework.AssertionFailedError
at junit.framework.Assert.fail(Assert.java:47)
at junit.framework.Assert.assertTrue(Assert.java:20)
at junit.framework.Assert.assertTrue(Assert.java:27)
at com.netbanking.testcases.TC_LoginDDT_002.loginDDT(TC_LoginDDT_002.java:37)
at java.base/jdk.internal.reflect.NativeMethodAccessorImpl.invoke0(Native Method)
at java.base/jdk.internal.reflect.NativeMethodAccessorImpl.invoke(Unknown Source)
at java.base/jdk.internal.reflect.DelegatingMethodAccessorImpl.invoke(Unknown Source)
at java.base/java.lang.reflect.Method.invoke(Unknown Source)
at org.testng.internal.MethodInvocationHelper.invokeMethod(MethodInvocationHelper.java:124)
at org.testng.internal.Invoker.invokeMethod(Invoker.java:583)
at org.testng.internal.Invoker.invokeTestMethod(Invoker.java:719)
at org.testng.internal.Invoker.invokeTestMethods(Invoker.java:989)
at org.testng.internal.TestMethodWorker.invokeTestMethods(TestMethodWorker.java:125)
at org.testng.internal.TestMethodWorker.run(TestMethodWorker.java:109)
at org.testng.TestRunner.privateRun(TestRunner.java:648)
at org.testng.TestRunner.run(TestRunner.java:505)
at org.testng.SuiteRunner.runTest(SuiteRunner.java:455)
at org.testng.SuiteRunner.runSequentially(SuiteRunner.java:450)
at org.testng.SuiteRunner.privateRun(SuiteRunner.java:415)
at org.testng.SuiteRunner.run(SuiteRunner.java:364)
at org.testng.SuiteRunnerWorker.runSuite(SuiteRunnerWorker.java:52)
at org.testng.SuiteRunnerWorker.run(SuiteRunnerWorker.java:84)
at org.testng.TestNG.runSuitesSequentially(TestNG.java:1208)
at org.testng.TestNG.runSuitesLocally(TestNG.java:1137)
at org.testng.TestNG.runSuites(TestNG.java:1049)
at org.testng.TestNG.run(TestNG.java:1017)
at org.testng.remote.AbstractRemoteTestNG.run(AbstractRemoteTestNG.java:114)
at org.testng.remote.RemoteTestNG.initAndRun(RemoteTestNG.java:251)
at org.testng.remote.RemoteTestNG.main(RemoteTestNG.java:77)
]]>
            </full-stacktrace>
          </exception> <!-- junit.framework.AssertionFailedError -->
          <reporter-output>
          </reporter-output>
        </test-method> <!-- loginDDT -->
        <test-method is-config="true" signature="tearDown()[pri:0, instance:com.netbanking.testcases.TC_LoginDDT_002@186f8716]" started-at="2020-02-01T10:09:15Z" name="tearDown" finished-at="2020-02-01T10:09:16Z" duration-ms="752" status="PASS">
          <reporter-output>
          </reporter-output>
        </test-method> <!-- tearDown -->
      </class> <!-- com.netbanking.testcases.TC_LoginDDT_002 -->
    </test> <!-- Default test(failed) -->
  </suite> <!-- Failed suite [Default suite] -->
</testng-results>
